loading annotations into memory...
Done (t=9.63s)
creating index...
index created!
Traceback (most recent call last):
  File "./lib/train.py", line 199, in <module>
    train() #debug/train
  File "./lib/train.py", line 144, in train
    loss, net = mask_rcnn(X, True, gt_boxes=gt_boxes, gt_classes=gt_classes, gt_masks=gt_masks)
  File "/home/andy/original-mask-rcnn/lib/mask_rcnn.py", line 76, in mask_rcnn
    rois['box'], gt_boxes, gt_classes, gt_masks)
  File "/home/andy/original-mask-rcnn/lib/targets.py", line 196, in classifier_targets
    tf.range(tf.shape(all_masks, 0)),
  File "/usr/local/lib/python2.7/dist-packages/tensorflow/python/ops/array_ops.py", line 285, in shape
    return shape_internal(input, name, optimize=True, out_type=out_type)
  File "/usr/local/lib/python2.7/dist-packages/tensorflow/python/ops/array_ops.py", line 313, in shape_internal
    return gen_array_ops.shape(input, name=name, out_type=out_type)
  File "/usr/local/lib/python2.7/dist-packages/tensorflow/python/ops/gen_array_ops.py", line 4462, in shape
    "Shape", input=input, out_type=out_type, name=name)
  File "/usr/local/lib/python2.7/dist-packages/tensorflow/python/framework/op_def_library.py", line 787, in _apply_op_helper
    op_def=op_def)
  File "/usr/local/lib/python2.7/dist-packages/tensorflow/python/framework/ops.py", line 3271, in create_op
    op_def=op_def)
  File "/usr/local/lib/python2.7/dist-packages/tensorflow/python/framework/ops.py", line 1589, in __init__
    raise ValueError("'%s' is not a valid node name" % node_def.name)
ValueError: '' is not a valid node name

real	0m16.378s
user	0m15.655s
sys	0m1.236s
